
try catch문을 사용하면 된다.
```js
function addOne(value){
	return new Promise((ok,no)=>{
	ok(value+1)
	})
}

function addOneReject(value){
	return new Promise((ok,no)=>{
	no(new Error(value+1+": 해당 과정에서 에러"))
	})
}

let startTask = async()=>{
	let task1 = await new Promise((ok,no)=>{ok(1)})
	let task2 = await addOne(task1);
	let task3 = await addOne(task2);
	let task4 = await addOneReject(task3); // 어기서 에러 발생
	let task5 = await addOne(task4);
	console.log(task5)
}
startTask();
```

에러 내용
![[에러 메세지.png]]